<?xml version="1.0" encoding="UTF-8"?>
<!-- Generated by org.testng.reporters.JUnitXMLReporter -->
<testsuite hostname="DESKTOP-I96GQ4S" name="Test" tests="4" failures="1" timestamp="6 Sep 2018 14:52:52 GMT" time="0.042" errors="0">
  <testcase name="arithmaticTest1" time="0.009" classname="mydemo.NewTestNG"/>
  <testcase name="arithmaticTest2" time="0.011" classname="mydemo.NewTestNG2"/>
  <testcase name="arithmaticTest1" time="0.014" classname="mydemo.NewTestNG2"/>
  <testcase name="arithmaticTest2" time="0.015" classname="mydemo.NewTestNG">
    <failure type="java.lang.AssertionError" message="expected [3] but found [2]">
      <![CDATA[java.lang.AssertionError: expected [3] but found [2]
	at mydemo.NewTestNG.arithmaticTest2(NewTestNG.java:24)
	at java.util.concurrent.ThreadPoolExecutor.runWorker(ThreadPoolExecutor.java:1149)
	at java.util.concurrent.ThreadPoolExecutor$Worker.run(ThreadPoolExecutor.java:624)
	at java.lang.Thread.run(Thread.java:748)
... Removed 15 stack frames]]>
    </failure>
  </testcase> <!-- arithmaticTest2 -->
</testsuite> <!-- Test -->
